<?xml version="1.0" encoding="utf-8"?>
<!-- =================================================================================== -->
<!-- |    This document was autogenerated by xacro from leo.urdf.xacro                 | -->
<!-- |    EDITING THIS FILE BY HAND IS NOT RECOMMENDED                                 | -->
<!-- =================================================================================== -->
<robot name="leo">
  <!-- ros_control plugin -->
  <gazebo>
    <plugin filename="libgazebo_ros_control.so" name="gazebo_ros_control">
      <robotNamespace>leo</robotNamespace>
      <robotSimType>gazebo_ros_control/DefaultRobotHWSim</robotSimType>
    </plugin>
  </gazebo>
  <!-- wheel ODE properties -->
  <gazebo reference="rocker_L_link">
    <kp>1e6</kp>
    <kd>1.0</kd>
    <minDepth>0.003</minDepth>
  </gazebo>
  <gazebo reference="rocker_R_link">
    <kp>1e6</kp>
    <kd>1.0</kd>
    <minDepth>0.003</minDepth>
  </gazebo>
  <gazebo reference="wheel_FL_link">
    <kp>1e6</kp>
    <kd>1.0</kd>
    <mu1>3.0</mu1>
    <mu2>0.5</mu2>
    <fdir1>1 0 0</fdir1>
    <minDepth>0.003</minDepth>
  </gazebo>
  <gazebo reference="wheel_FR_link">
    <kp>1e6</kp>
    <kd>1.0</kd>
    <mu1>3.0</mu1>
    <mu2>0.5</mu2>
    <fdir1>1 0 0</fdir1>
    <minDepth>0.003</minDepth>
  </gazebo>
  <gazebo reference="wheel_RL_link">
    <kp>1e6</kp>
    <kd>1.0</kd>
    <mu1>3.0</mu1>
    <mu2>0.5</mu2>
    <fdir1>1 0 0</fdir1>
    <minDepth>0.003</minDepth>
  </gazebo>
  <gazebo reference="wheel_RR_link">
    <kp>1e6</kp>
    <kd>1.0</kd>
    <mu1>3.0</mu1>
    <mu2>0.5</mu2>
    <fdir1>1 0 0</fdir1>
    <minDepth>0.003</minDepth>
  </gazebo>
  <!-- camera -->
  <gazebo reference="camera_frame">
    <sensor name="leo_camera" type="camera">
      <always_on>true</always_on>
      <update_rate>30.0</update_rate>
      <visualize>false</visualize>
      <camera name="leo_camera">
        <horizontal_fov>1.9</horizontal_fov>
        <image>
          <width>640</width>
          <height>480</height>
          <format>R8G8B8</format>
        </image>
        <clip>
          <near>0.02</near>
          <far>300</far>
        </clip>
        <noise>
          <type>gaussian</type>
          <mean>0.0</mean>
          <stddev>0.007</stddev>
        </noise>
        <distortion>
          <k1>-0.279817</k1>
          <k2>0.060321</k2>
          <k3>0.000487</k3>
          <p1>0.000310</p1>
          <p2>0.000000</p2>
          <center>0.5 0.5</center>
        </distortion>
      </camera>
      <plugin filename="libgazebo_ros_camera.so" name="camera_controller">
        <robotNamespace>leo</robotNamespace>
        <cameraName>camera</cameraName>
        <imageTopicName>image_raw</imageTopicName>
        <cameraInfoTopicName>camera_info</cameraInfoTopicName>
        <frameName>camera_optical_frame</frameName>
        <distortionK1>-0.279817</distortionK1>
        <distortionK2>0.060321</distortionK2>
        <distortionK3>0.000487</distortionK3>
        <distortionT1>0.000310</distortionT1>
        <distortionT2>0.000000</distortionT2>
      </plugin>
    </sensor>
  </gazebo>
  <!-- Left/Depth camera -->
  <gazebo reference="zed2_left_camera_frame">
    <!-- Raw images (with lens distortion) -->
    <sensor name="zed2_left_raw_camera" type="camera">
      <always_on>true</always_on>
      <update_rate>15.0</update_rate>
      <visualize>false</visualize>
      <camera name="zed2_left_raw">
        <horizontal_fov>1.7633</horizontal_fov>
        <image>
          <width>1280</width>
          <height>720</height>
          <format>R8G8B8</format>
        </image>
        <clip>
          <near>0.02</near>
          <far>300</far>
        </clip>
        <noise>
          <type>gaussian</type>
          <mean>0.0</mean>
          <stddev>0.007</stddev>
        </noise>
        <distortion>
          <!-- Values copied from an actual ZED2 camera -->
          <k1>-0.043693598</k1>
          <k2>0.0146164996</k2>
          <p1>-0.006573319</p1>
          <p2>-0.000216900</p2>
          <k3>0.000084328</k3>
          <center>0.5 0.5</center>
        </distortion>
      </camera>
      <plugin filename="libgazebo_ros_camera.so" name="camera_controller">
        <robotNamespace>leo</robotNamespace>
        <cameraName>zed2/left_raw</cameraName>
        <imageTopicName>image_raw_color</imageTopicName>
        <cameraInfoTopicName>camera_info</cameraInfoTopicName>
        <frameName>zed2_left_camera_optical_frame</frameName>
        <distortionK1>-0.043693598</distortionK1>
        <distortionK2>0.0146164996</distortionK2>
        <distortionT1>-0.006573319</distortionT1>
        <distortionT2>-0.000216900</distortionT2>
        <distortionK3>0.000084328</distortionK3>
        <CxPrime>648.5</CxPrime>
        <Cx>648.5</Cx>
        <Cy>366.8340148925781</Cy>
        <hackBaseline>0.0</hackBaseline>
      </plugin>
    </sensor>
    <sensor name="zed2_left_camera" type="depth">
      <!-- Rectified images, Depth images, Point Clouds -->
      <always_on>true</always_on>
      <update_rate>15.0</update_rate>
      <visualize>false</visualize>
      <camera name="zed2_left">
        <horizontal_fov>1.7633</horizontal_fov>
        <image>
          <width>1280</width>
          <height>720</height>
          <format>R8G8B8</format>
        </image>
        <clip>
          <near>0.02</near>
          <far>300</far>
        </clip>
        <noise>
          <type>gaussian</type>
          <mean>0.0</mean>
          <stddev>0.007</stddev>
        </noise>
      </camera>
      <plugin filename="libgazebo_ros_openni_kinect.so" name="camera_controller">
        <robotNamespace>leo</robotNamespace>
        <cameraName>zed2</cameraName>
        <imageTopicName>left/image_rect_color</imageTopicName>
        <cameraInfoTopicName>left/camera_info</cameraInfoTopicName>
        <depthImageTopicName>depth/depth_registered</depthImageTopicName>
        <depthImageInfoTopicName>depth/camera_info</depthImageInfoTopicName>
        <pointCloudTopicName>point_cloud/cloud_registered</pointCloudTopicName>
        <pointCloudCutoff>0.3</pointCloudCutoff>
        <pointCloudCutoffMax>20.0</pointCloudCutoffMax>
        <frameName>zed2_left_camera_optical_frame</frameName>
        <baseline>0.12</baseline>
        <CxPrime>658.8206787109375</CxPrime>
        <Cx>658.8206787109375</Cx>
        <Cy>372.25787353515625</Cy>
        <hackBaseline>0.0</hackBaseline>
      </plugin>
    </sensor>
  </gazebo>
  <!-- Right camera -->
  <gazebo reference="zed2_right_camera_frame">
    <!-- Raw images (with lens distortion) -->
    <sensor name="zed2_right_raw_camera" type="camera">
      <always_on>true</always_on>
      <update_rate>15.0</update_rate>
      <visualize>false</visualize>
      <camera name="zed2_right_raw">
        <horizontal_fov>1.7633</horizontal_fov>
        <image>
          <width>1280</width>
          <height>720</height>
          <format>R8G8B8</format>
        </image>
        <clip>
          <near>0.02</near>
          <far>300</far>
        </clip>
        <noise>
          <type>gaussian</type>
          <mean>0.0</mean>
          <stddev>0.007</stddev>
        </noise>
        <distortion>
          <k1>-0.040993299</k1>
          <k2>0.009593590</k2>
          <p1>-0.004429849</p1>
          <p2>0.000192024</p2>
          <k3>-0.000320880</k3>
          <center>0.5 0.5</center>
        </distortion>
      </camera>
      <plugin filename="libgazebo_ros_camera.so" name="camera_controller">
        <robotNamespace>leo</robotNamespace>
        <cameraName>zed2/right_raw</cameraName>
        <imageTopicName>image_raw_color</imageTopicName>
        <cameraInfoTopicName>camera_info</cameraInfoTopicName>
        <frameName>zed2_right_camera_optical_frame</frameName>
        <distortionK1>-0.040993299</distortionK1>
        <distortionK2>0.009593590</distortionK2>
        <distortionT1>-0.004429849</distortionT1>
        <distortionT2>0.000192024</distortionT2>
        <distortionK3>-0.000320880</distortionK3>
        <CxPrime>659.3049926757812</CxPrime>
        <Cx>659.3049926757812</Cx>
        <Cy>371.39849853515625</Cy>
        <hackBaseline>0.12</hackBaseline>
      </plugin>
    </sensor>
    <sensor name="zed2_right_camera" type="camera">
      <!-- Rectified images -->
      <always_on>true</always_on>
      <update_rate>15.0</update_rate>
      <visualize>false</visualize>
      <camera name="zed2_right">
        <horizontal_fov>1.7633</horizontal_fov>
        <image>
          <width>1280</width>
          <height>720</height>
          <format>R8G8B8</format>
        </image>
        <clip>
          <near>0.02</near>
          <far>300</far>
        </clip>
        <noise>
          <type>gaussian</type>
          <mean>0.0</mean>
          <stddev>0.007</stddev>
        </noise>
      </camera>
      <plugin filename="libgazebo_ros_camera.so" name="camera_controller">
        <robotNamespace>leo</robotNamespace>
        <cameraName>zed2/right</cameraName>
        <imageTopicName>image_rect_color</imageTopicName>
        <cameraInfoTopicName>camera_info</cameraInfoTopicName>
        <frameName>zed2_right_camera_optical_frame</frameName>
        <CxPrime>658.8206787109375</CxPrime>
        <Cx>658.8206787109375</Cx>
        <Cy>372.25787353515625</Cy>
        <hackBaseline>0.12</hackBaseline>
      </plugin>
    </sensor>
  </gazebo>
  <!-- IMU -->
  <gazebo reference="zed2_left_camera_frame">
    <sensor name="zed2_imu_sensor" type="imu">
      <update_rate>100</update_rate>
      <plugin filename="libgazebo_ros_imu_sensor.so" name="imu_plugin">
        <robotNamespace>leo</robotNamespace>
        <topicName>zed2/imu/data</topicName>
        <frameName>zed2_imu_link</frameName>
        <bodyName>imu_link</bodyName>
        <updateRateHZ>100.0</updateRateHZ>
        <gaussianNoise>0.0</gaussianNoise>
        <initialOrientationAsReference>false</initialOrientationAsReference>
        <!-- IMU frame offset copied from an actual ZED2 camera -->
        <xyzOffset>-0.002 -0.023 -0.002</xyzOffset>
        <rpyOffset>0.0014025 -0.0000012 -0.0016915</rpyOffset>
      </plugin>
    </sensor>
  </gazebo>
  <!-- Camera Center -->
  <joint name="zed2_camera_center_joint" type="fixed">
    <parent link="zed2_tilt_head_link"/>
    <child link="zed2_camera_center"/>
    <origin rpy="0 0.032637657 0" xyz="0 0 0.0486"/>
  </joint>
  <link name="zed2_camera_center">
    <inertial>
      <mass value="0.16140"/>
      <origin xyz="0 0 0"/>
      <inertia ixx="0.0003947" ixy="0.0" ixz="3.3365e-8" iyy="2.417e-5" iyz="0.0" izz="0.0003973"/>
    </inertial>
    <visual>
      <geometry>
        <mesh filename="package://leo_description/models/ZED2.dae"/>
      </geometry>
    </visual>
    <collision>
      <geometry>
        <mesh filename="package://leo_description/models/ZED2.dae"/>
      </geometry>
    </collision>
  </link>
  <!-- Left Camera -->
  <joint name="zed2_left_camera_joint" type="fixed">
    <parent link="zed2_camera_center"/>
    <child link="zed2_left_camera_frame"/>
    <origin rpy="0 0 0" xyz="0 0.06 0"/>
  </joint>
  <link name="zed2_left_camera_frame"/>
  <joint name="zed2_left_camera_optical_joint" type="fixed">
    <origin rpy="-1.57079632679 0.0 -1.57079632679" xyz="0 0 0"/>
    <parent link="zed2_left_camera_frame"/>
    <child link="zed2_left_camera_optical_frame"/>
  </joint>
  <link name="zed2_left_camera_optical_frame"/>
  <!-- Right Camera -->
  <joint name="zed2_right_camera_joint" type="fixed">
    <parent link="zed2_camera_center"/>
    <child link="zed2_right_camera_frame"/>
    <origin rpy="0 0 0" xyz="0 -0.06 0"/>
  </joint>
  <link name="zed2_right_camera_frame"/>
  <joint name="zed2_right_camera_optical_joint" type="fixed">
    <origin rpy="-1.57079632679 0.0 -1.57079632679" xyz="0 0 0"/>
    <parent link="zed2_right_camera_frame"/>
    <child link="zed2_right_camera_optical_frame"/>
  </joint>
  <link name="zed2_right_camera_optical_frame"/>
  <!-- Sensors -->
  <joint name="zed2_mag_joint" type="fixed">
    <parent link="zed2_camera_center"/>
    <child link="zed2_mag_link"/>
    <origin rpy="0 0 0" xyz="0 0 0"/>
  </joint>
  <link name="zed2_mag_link"/>
  <joint name="zed2_baro_joint" type="fixed">
    <parent link="zed2_camera_center"/>
    <child link="zed2_baro_link"/>
    <origin rpy="0 0 0" xyz="0 0 0"/>
  </joint>
  <link name="zed2_baro_link"/>
  <joint name="zed2_temp_left_joint" type="fixed">
    <parent link="zed2_left_camera_frame"/>
    <child link="zed2_temp_left_link"/>
    <origin rpy="0 0 0" xyz="0 0 0"/>
  </joint>
  <link name="zed2_temp_left_link"/>
  <joint name="zed2_temp_right_joint" type="fixed">
    <parent link="zed2_right_camera_frame"/>
    <child link="zed2_temp_right_link"/>
    <origin rpy="0 0 0" xyz="0 0 0"/>
  </joint>
  <link name="zed2_temp_right_link"/>
  <joint name="erc_setup_joint" type="fixed">
    <origin rpy="0 0 0" xyz="0.048 0 0"/>
    <parent link="base_link"/>
    <child link="erc_setup_link"/>
  </joint>
  <link name="erc_setup_link">
    <inertial>
      <mass value="1.10026"/>
      <origin xyz="-0.068748 0.019099 0.07874"/>
      <inertia ixx="0.006365" ixy="-0.0002913" ixz="-0.001492" iyy="0.009844" iyz="-0.0008438" izz="0.006101"/>
    </inertial>
    <visual>
      <geometry>
        <mesh filename="package://leo_description/models/ERC2020setup.dae"/>
      </geometry>
    </visual>
    <collision>
      <geometry>
        <mesh filename="package://leo_description/models/ERC2020setup_outline.dae"/>
      </geometry>
    </collision>
  </link>
  <joint name="zed2_tilt_head_joint" type="fixed">
    <origin rpy="0 0.415911961 0" xyz="0 0 0.1291"/>
    <!-- 23.83 degree tilt -->
    <parent link="erc_setup_link"/>
    <child link="zed2_tilt_head_link"/>
  </joint>
  <link name="zed2_tilt_head_link">
    <inertial>
      <mass value="0.108614"/>
      <origin xyz="0 -0.008564 0.015313"/>
      <inertia ixx="7.371e-5" ixy="0.0" ixz="1.326071e-6" iyy="3.14e-5" iyz="-1.424e-5" izz="6.13e-5"/>
    </inertial>
    <visual>
      <geometry>
        <mesh filename="package://leo_description/models/Manfrotto_head.dae"/>
      </geometry>
    </visual>
    <collision>
      <geometry>
        <mesh filename="package://leo_description/models/Manfrotto_head.dae"/>
      </geometry>
    </collision>
  </link>
  <!-- MACROS -->
  <!-- LINKS -->
  <link name="base_link">
    <inertial>
      <mass value="1.584994"/>
      <origin xyz="-0.019662 0.011643 -0.031802"/>
      <inertia ixx="0.01042" ixy="0.001177" ixz="-0.0008871" iyy="0.01045" iyz="0.0002226" izz="0.01817"/>
    </inertial>
    <visual>
      <geometry>
        <mesh filename="package://leo_description/models/Chassis.dae"/>
      </geometry>
    </visual>
    <collision>
      <geometry>
        <mesh filename="package://leo_description/models/Chassis_outline.stl"/>
      </geometry>
    </collision>
  </link>
  <link name="base_footprint"/>
  <link name="rocker_L_link">
    <inertial>
      <mass value="1.387336"/>
      <origin xyz="0 0.01346 -0.06506"/>
      <inertia ixx="0.002956" ixy="-0.000001489324" ixz="-0.000008103407" iyy="0.02924" iyz="0.00007112" izz="0.02832"/>
    </inertial>
    <visual>
      <geometry>
        <mesh filename="package://leo_description/models/Rocker.dae"/>
      </geometry>
    </visual>
    <collision>
      <geometry>
        <mesh filename="package://leo_description/models/Rocker_outline.stl"/>
      </geometry>
    </collision>
  </link>
  <link name="rocker_R_link">
    <inertial>
      <mass value="1.387336"/>
      <origin xyz="0 0.01346 -0.06506"/>
      <inertia ixx="0.002956" ixy="-0.000001489324" ixz="-0.000008103407" iyy="0.02924" iyz="0.00007112" izz="0.02832"/>
    </inertial>
    <visual>
      <geometry>
        <mesh filename="package://leo_description/models/Rocker.dae"/>
      </geometry>
    </visual>
    <collision>
      <geometry>
        <mesh filename="package://leo_description/models/Rocker_outline.stl"/>
      </geometry>
    </collision>
  </link>
  <link name="wheel_FL_link">
    <inertial>
      <mass value="0.283642"/>
      <origin xyz="0 0.030026 0"/>
      <inertia ixx="0.000391" ixy="0.00000123962" ixz="5.52582e-7" iyy="0.0004716" iyz="-0.000002082042" izz="0.000391"/>
    </inertial>
    <visual>
      <geometry>
        <mesh filename="package://leo_description/models/WheelA.dae"/>
      </geometry>
    </visual>
    <collision>
      <origin rpy="1.57079632679 0 0" xyz="0 0.04485 0"/>
      <geometry>
        <cylinder length="0.07" radius="0.057"/>
      </geometry>
    </collision>
    <collision>
      <origin rpy="1.57079632679 0 0" xyz="0 0.04485 0"/>
      <geometry>
        <cylinder length="0.04" radius="0.0625"/>
      </geometry>
    </collision>
    <collision>
      <geometry>
        <mesh filename="package://leo_description/models/Wheel_outline.stl"/>
      </geometry>
    </collision>
  </link>
  <link name="wheel_RL_link">
    <inertial>
      <mass value="0.283642"/>
      <origin xyz="0 0.030026 0"/>
      <inertia ixx="0.000391" ixy="0.00000123962" ixz="5.52582e-7" iyy="0.0004716" iyz="-0.000002082042" izz="0.000391"/>
    </inertial>
    <visual>
      <geometry>
        <mesh filename="package://leo_description/models/WheelA.dae"/>
      </geometry>
    </visual>
    <collision>
      <origin rpy="1.57079632679 0 0" xyz="0 0.04485 0"/>
      <geometry>
        <cylinder length="0.07" radius="0.057"/>
      </geometry>
    </collision>
    <collision>
      <origin rpy="1.57079632679 0 0" xyz="0 0.04485 0"/>
      <geometry>
        <cylinder length="0.04" radius="0.0625"/>
      </geometry>
    </collision>
    <collision>
      <geometry>
        <mesh filename="package://leo_description/models/Wheel_outline.stl"/>
      </geometry>
    </collision>
  </link>
  <link name="wheel_FR_link">
    <inertial>
      <mass value="0.283642"/>
      <origin xyz="0 0.030026 0"/>
      <inertia ixx="0.000391" ixy="0.00000123962" ixz="5.52582e-7" iyy="0.0004716" iyz="-0.000002082042" izz="0.000391"/>
    </inertial>
    <visual>
      <geometry>
        <mesh filename="package://leo_description/models/WheelB.dae"/>
      </geometry>
    </visual>
    <collision>
      <origin rpy="1.57079632679 0 0" xyz="0 0.04485 0"/>
      <geometry>
        <cylinder length="0.07" radius="0.057"/>
      </geometry>
    </collision>
    <collision>
      <origin rpy="1.57079632679 0 0" xyz="0 0.04485 0"/>
      <geometry>
        <cylinder length="0.04" radius="0.0625"/>
      </geometry>
    </collision>
    <collision>
      <geometry>
        <mesh filename="package://leo_description/models/Wheel_outline.stl"/>
      </geometry>
    </collision>
  </link>
  <link name="wheel_RR_link">
    <inertial>
      <mass value="0.283642"/>
      <origin xyz="0 0.030026 0"/>
      <inertia ixx="0.000391" ixy="0.00000123962" ixz="5.52582e-7" iyy="0.0004716" iyz="-0.000002082042" izz="0.000391"/>
    </inertial>
    <visual>
      <geometry>
        <mesh filename="package://leo_description/models/WheelB.dae"/>
      </geometry>
    </visual>
    <collision>
      <origin rpy="1.57079632679 0 0" xyz="0 0.04485 0"/>
      <geometry>
        <cylinder length="0.07" radius="0.057"/>
      </geometry>
    </collision>
    <collision>
      <origin rpy="1.57079632679 0 0" xyz="0 0.04485 0"/>
      <geometry>
        <cylinder length="0.04" radius="0.0625"/>
      </geometry>
    </collision>
    <collision>
      <geometry>
        <mesh filename="package://leo_description/models/Wheel_outline.stl"/>
      </geometry>
    </collision>
  </link>
  <link name="camera_frame"/>
  <link name="camera_optical_frame"/>
  <!-- JOINTS -->
  <joint name="rocker_L_joint" type="fixed">
    <origin rpy="0 0 3.14159265359" xyz="0.00263 0.14167 -0.04731"/>
    <parent link="base_link"/>
    <child link="rocker_L_link"/>
    <axis xyz="0 1 0"/>
    <limit effort="100.0" lower="-0.24" upper="0.24" velocity="100.0"/>
    <dynamics damping="0.1" friction="1.0"/>
  </joint>
  <joint name="rocker_R_joint" type="fixed">
    <origin rpy="0 0 0" xyz="0.00263 -0.14167 -0.04731"/>
    <parent link="base_link"/>
    <child link="rocker_R_link"/>
    <axis xyz="0 1 0"/>
    <limit effort="100.0" lower="-0.24" upper="0.24" velocity="100.0"/>
    <dynamics damping="0.1" friction="1.0"/>
    <mimic joint="rocker_L_joint"/>
  </joint>
  <joint name="wheel_FL_joint" type="continuous">
    <origin rpy="0 0 0" xyz="-0.15256 -0.08214 -0.08802"/>
    <parent link="rocker_L_link"/>
    <child link="wheel_FL_link"/>
    <axis xyz="0 -1 0"/>
    <limit effort="2.0" velocity="6.0"/>
    <dynamics damping="0.1" friction="0.3125"/>
  </joint>
  <joint name="wheel_RL_joint" type="continuous">
    <origin rpy="0 0 0" xyz="0.15256 -0.08214 -0.08802"/>
    <parent link="rocker_L_link"/>
    <child link="wheel_RL_link"/>
    <axis xyz="0 -1 0"/>
    <limit effort="2.0" velocity="6.0"/>
    <dynamics damping="0.1" friction="0.3125"/>
  </joint>
  <joint name="wheel_FR_joint" type="continuous">
    <origin rpy="0 0 0" xyz="-0.15256 -0.08214 -0.08802"/>
    <parent link="rocker_R_link"/>
    <child link="wheel_FR_link"/>
    <axis xyz="0 1 0"/>
    <limit effort="2.0" velocity="6.0"/>
    <dynamics damping="0.1" friction="0.3125"/>
  </joint>
  <joint name="wheel_RR_joint" type="continuous">
    <origin rpy="0 0 0" xyz="0.15256 -0.08214 -0.08802"/>
    <parent link="rocker_R_link"/>
    <child link="wheel_RR_link"/>
    <axis xyz="0 1 0"/>
    <limit effort="2.0" velocity="6.0"/>
    <dynamics damping="0.1" friction="0.3125"/>
  </joint>
  <joint name="camera_joint" type="fixed">
    <origin rpy="0 0.2094 0" xyz="0.0971 0 -0.0427"/>
    <parent link="base_link"/>
    <child link="camera_frame"/>
  </joint>
  <joint name="camera_optical_joint" type="fixed">
    <origin rpy="-1.57079632679 0.0 -1.57079632679" xyz="0 0 0"/>
    <parent link="camera_frame"/>
    <child link="camera_optical_frame"/>
  </joint>
  <joint name="footprint_joint" type="fixed">
    <origin rpy="0 0 0" xyz="0 0 -0.19783"/>
    <parent link="base_link"/>
    <child link="base_footprint"/>
  </joint>
  <!-- TRANSMISSIONS -->
  <transmission name="wheel_FL_trans">
    <type>transmission_interface/SimpleTransmission</type>
    <joint name="wheel_FL_joint">
      <hardwareInterface>hardware_interface/VelocityJointInterface</hardwareInterface>
    </joint>
    <actuator name="wheel_FL_motor">
      <mechanicalReduction>1</mechanicalReduction>
      <hardwareInterface>hardware_interface/VelocityJointInterface</hardwareInterface>
    </actuator>
  </transmission>
  <transmission name="wheel_RL_trans">
    <type>transmission_interface/SimpleTransmission</type>
    <joint name="wheel_RL_joint">
      <hardwareInterface>hardware_interface/VelocityJointInterface</hardwareInterface>
    </joint>
    <actuator name="wheel_RL_motor">
      <mechanicalReduction>1</mechanicalReduction>
      <hardwareInterface>hardware_interface/VelocityJointInterface</hardwareInterface>
    </actuator>
  </transmission>
  <transmission name="wheel_FR_trans">
    <type>transmission_interface/SimpleTransmission</type>
    <joint name="wheel_FR_joint">
      <hardwareInterface>hardware_interface/VelocityJointInterface</hardwareInterface>
    </joint>
    <actuator name="wheel_FR_motor">
      <mechanicalReduction>1</mechanicalReduction>
      <hardwareInterface>hardware_interface/VelocityJointInterface</hardwareInterface>
    </actuator>
  </transmission>
  <transmission name="wheel_RR_trans">
    <type>transmission_interface/SimpleTransmission</type>
    <joint name="wheel_RR_joint">
      <hardwareInterface>hardware_interface/VelocityJointInterface</hardwareInterface>
    </joint>
    <actuator name="wheel_RR_motor">
      <mechanicalReduction>1</mechanicalReduction>
      <hardwareInterface>hardware_interface/VelocityJointInterface</hardwareInterface>
    </actuator>
  </transmission>
</robot>
